[2025-01-11T20:29:00.206+0000] {local_task_job_runner.py:123} INFO - ::group::Pre task execution logs
[2025-01-11T20:29:00.219+0000] {taskinstance.py:2613} INFO - Dependencies all met for dep_context=non-requeueable deps ti=<TaskInstance: my_first_dbt_dag.run_dbt_model manual__2025-01-11T20:23:54.050877+00:00 [queued]>
[2025-01-11T20:29:00.226+0000] {taskinstance.py:2613} INFO - Dependencies all met for dep_context=requeueable deps ti=<TaskInstance: my_first_dbt_dag.run_dbt_model manual__2025-01-11T20:23:54.050877+00:00 [queued]>
[2025-01-11T20:29:00.227+0000] {taskinstance.py:2866} INFO - Starting attempt 2 of 2
[2025-01-11T20:29:00.241+0000] {taskinstance.py:2889} INFO - Executing <Task(PythonOperator): run_dbt_model> on 2025-01-11 20:23:54.050877+00:00
[2025-01-11T20:29:00.247+0000] {standard_task_runner.py:104} INFO - Running: ['***', 'tasks', 'run', 'my_first_dbt_dag', 'run_dbt_model', 'manual__2025-01-11T20:23:54.050877+00:00', '--job-id', '16', '--raw', '--subdir', 'DAGS_FOLDER/my_first_dbt_dag.py', '--cfg-path', '/tmp/tmpfjh8f2ec']
[2025-01-11T20:29:00.252+0000] {standard_task_runner.py:105} INFO - Job 16: Subtask run_dbt_model
[2025-01-11T20:29:00.252+0000] {logging_mixin.py:190} WARNING - /home/***/.local/lib/python3.12/site-packages/***/task/task_runner/standard_task_runner.py:70 DeprecationWarning: This process (pid=4144) is multi-threaded, use of fork() may lead to deadlocks in the child.
[2025-01-11T20:29:00.253+0000] {standard_task_runner.py:72} INFO - Started process 4145 to run task
[2025-01-11T20:29:00.298+0000] {task_command.py:467} INFO - Running <TaskInstance: my_first_dbt_dag.run_dbt_model manual__2025-01-11T20:23:54.050877+00:00 [running]> on host fa9e0c048884
[2025-01-11T20:29:00.385+0000] {taskinstance.py:3132} INFO - Exporting env vars: AIRFLOW_CTX_DAG_OWNER='***' AIRFLOW_CTX_DAG_ID='my_first_dbt_dag' AIRFLOW_CTX_TASK_ID='run_dbt_model' AIRFLOW_CTX_EXECUTION_DATE='2025-01-11T20:23:54.050877+00:00' AIRFLOW_CTX_TRY_NUMBER='2' AIRFLOW_CTX_DAG_RUN_ID='manual__2025-01-11T20:23:54.050877+00:00'
[2025-01-11T20:29:00.386+0000] {taskinstance.py:731} INFO - ::endgroup::
[2025-01-11T20:29:03.054+0000] {logging_mixin.py:190} INFO - DBT command failed: Command '['dbt', 'run', '--project-dir', '/opt/dbt-project', '--select', 'my_first_dbt_model']' returned non-zero exit status 2.
[2025-01-11T20:29:03.054+0000] {logging_mixin.py:190} INFO - Error output:
Usage: dbt run [OPTIONS]
Try 'dbt run -h' for help.

Error: Invalid value for '--profiles-dir': Path '/opt/dbt-project/profiles' does not exist.
[2025-01-11T20:29:03.055+0000] {taskinstance.py:3311} ERROR - Task failed with exception
Traceback (most recent call last):
  File "/home/airflow/.local/lib/python3.12/site-packages/airflow/models/taskinstance.py", line 767, in _execute_task
    result = _execute_callable(context=context, **execute_callable_kwargs)
             ^^^^^^^^^^^^^^^^^^^^^^^^^^^^^^^^^^^^^^^^^^^^^^^^^^^^^^^^^^^^^
  File "/home/airflow/.local/lib/python3.12/site-packages/airflow/models/taskinstance.py", line 733, in _execute_callable
    return ExecutionCallableRunner(
           ^^^^^^^^^^^^^^^^^^^^^^^^
  File "/home/airflow/.local/lib/python3.12/site-packages/airflow/utils/operator_helpers.py", line 252, in run
    return self.func(*args, **kwargs)
           ^^^^^^^^^^^^^^^^^^^^^^^^^^
  File "/home/airflow/.local/lib/python3.12/site-packages/airflow/models/baseoperator.py", line 422, in wrapper
    return func(self, *args, **kwargs)
           ^^^^^^^^^^^^^^^^^^^^^^^^^^^
  File "/home/airflow/.local/lib/python3.12/site-packages/airflow/operators/python.py", line 238, in execute
    return_value = self.execute_callable()
                   ^^^^^^^^^^^^^^^^^^^^^^^
  File "/home/airflow/.local/lib/python3.12/site-packages/airflow/operators/python.py", line 256, in execute_callable
    return runner.run(*self.op_args, **self.op_kwargs)
           ^^^^^^^^^^^^^^^^^^^^^^^^^^^^^^^^^^^^^^^^^^^
  File "/home/airflow/.local/lib/python3.12/site-packages/airflow/utils/operator_helpers.py", line 252, in run
    return self.func(*args, **kwargs)
           ^^^^^^^^^^^^^^^^^^^^^^^^^^
  File "/opt/airflow/dags/my_first_dbt_dag.py", line 16, in run_dbt_model
    result = subprocess.run(
             ^^^^^^^^^^^^^^^
  File "/usr/local/lib/python3.12/subprocess.py", line 571, in run
    raise CalledProcessError(retcode, process.args,
subprocess.CalledProcessError: Command '['dbt', 'run', '--project-dir', '/opt/dbt-project', '--select', 'my_first_dbt_model']' returned non-zero exit status 2.
[2025-01-11T20:29:03.065+0000] {taskinstance.py:1225} INFO - Marking task as FAILED. dag_id=my_first_dbt_dag, task_id=run_dbt_model, run_id=manual__2025-01-11T20:23:54.050877+00:00, execution_date=20250111T202354, start_date=20250111T202900, end_date=20250111T202903
[2025-01-11T20:29:03.077+0000] {taskinstance.py:340} INFO - ::group::Post task execution logs
[2025-01-11T20:29:03.078+0000] {standard_task_runner.py:124} ERROR - Failed to execute job 16 for task run_dbt_model (Command '['dbt', 'run', '--project-dir', '/opt/dbt-project', '--select', 'my_first_dbt_model']' returned non-zero exit status 2.; 4145)
Traceback (most recent call last):
  File "/home/airflow/.local/lib/python3.12/site-packages/airflow/task/task_runner/standard_task_runner.py", line 117, in _start_by_fork
    ret = args.func(args, dag=self.dag)
          ^^^^^^^^^^^^^^^^^^^^^^^^^^^^^
  File "/home/airflow/.local/lib/python3.12/site-packages/airflow/cli/cli_config.py", line 49, in command
    return func(*args, **kwargs)
           ^^^^^^^^^^^^^^^^^^^^^
  File "/home/airflow/.local/lib/python3.12/site-packages/airflow/utils/cli.py", line 116, in wrapper
    return f(*args, **kwargs)
           ^^^^^^^^^^^^^^^^^^
  File "/home/airflow/.local/lib/python3.12/site-packages/airflow/cli/commands/task_command.py", line 483, in task_run
    task_return_code = _run_task_by_selected_method(args, _dag, ti)
                       ^^^^^^^^^^^^^^^^^^^^^^^^^^^^^^^^^^^^^^^^^^^^
  File "/home/airflow/.local/lib/python3.12/site-packages/airflow/cli/commands/task_command.py", line 256, in _run_task_by_selected_method
    return _run_raw_task(args, ti)
           ^^^^^^^^^^^^^^^^^^^^^^^
  File "/home/airflow/.local/lib/python3.12/site-packages/airflow/cli/commands/task_command.py", line 341, in _run_raw_task
    return ti._run_raw_task(
           ^^^^^^^^^^^^^^^^^
  File "/home/airflow/.local/lib/python3.12/site-packages/airflow/utils/session.py", line 97, in wrapper
    return func(*args, session=session, **kwargs)
           ^^^^^^^^^^^^^^^^^^^^^^^^^^^^^^^^^^^^^^
  File "/home/airflow/.local/lib/python3.12/site-packages/airflow/models/taskinstance.py", line 3005, in _run_raw_task
    return _run_raw_task(
           ^^^^^^^^^^^^^^
  File "/home/airflow/.local/lib/python3.12/site-packages/airflow/models/taskinstance.py", line 273, in _run_raw_task
    TaskInstance._execute_task_with_callbacks(
  File "/home/airflow/.local/lib/python3.12/site-packages/airflow/models/taskinstance.py", line 3159, in _execute_task_with_callbacks
    result = self._execute_task(context, task_orig)
             ^^^^^^^^^^^^^^^^^^^^^^^^^^^^^^^^^^^^^^
  File "/home/airflow/.local/lib/python3.12/site-packages/airflow/models/taskinstance.py", line 3183, in _execute_task
    return _execute_task(self, context, task_orig)
           ^^^^^^^^^^^^^^^^^^^^^^^^^^^^^^^^^^^^^^^
  File "/home/airflow/.local/lib/python3.12/site-packages/airflow/models/taskinstance.py", line 767, in _execute_task
    result = _execute_callable(context=context, **execute_callable_kwargs)
             ^^^^^^^^^^^^^^^^^^^^^^^^^^^^^^^^^^^^^^^^^^^^^^^^^^^^^^^^^^^^^
  File "/home/airflow/.local/lib/python3.12/site-packages/airflow/models/taskinstance.py", line 733, in _execute_callable
    return ExecutionCallableRunner(
           ^^^^^^^^^^^^^^^^^^^^^^^^
  File "/home/airflow/.local/lib/python3.12/site-packages/airflow/utils/operator_helpers.py", line 252, in run
    return self.func(*args, **kwargs)
           ^^^^^^^^^^^^^^^^^^^^^^^^^^
  File "/home/airflow/.local/lib/python3.12/site-packages/airflow/models/baseoperator.py", line 422, in wrapper
    return func(self, *args, **kwargs)
           ^^^^^^^^^^^^^^^^^^^^^^^^^^^
  File "/home/airflow/.local/lib/python3.12/site-packages/airflow/operators/python.py", line 238, in execute
    return_value = self.execute_callable()
                   ^^^^^^^^^^^^^^^^^^^^^^^
  File "/home/airflow/.local/lib/python3.12/site-packages/airflow/operators/python.py", line 256, in execute_callable
    return runner.run(*self.op_args, **self.op_kwargs)
           ^^^^^^^^^^^^^^^^^^^^^^^^^^^^^^^^^^^^^^^^^^^
  File "/home/airflow/.local/lib/python3.12/site-packages/airflow/utils/operator_helpers.py", line 252, in run
    return self.func(*args, **kwargs)
           ^^^^^^^^^^^^^^^^^^^^^^^^^^
  File "/opt/airflow/dags/my_first_dbt_dag.py", line 16, in run_dbt_model
    result = subprocess.run(
             ^^^^^^^^^^^^^^^
  File "/usr/local/lib/python3.12/subprocess.py", line 571, in run
    raise CalledProcessError(retcode, process.args,
subprocess.CalledProcessError: Command '['dbt', 'run', '--project-dir', '/opt/dbt-project', '--select', 'my_first_dbt_model']' returned non-zero exit status 2.
[2025-01-11T20:29:03.122+0000] {local_task_job_runner.py:266} INFO - Task exited with return code 1
[2025-01-11T20:29:03.135+0000] {taskinstance.py:3895} INFO - 0 downstream tasks scheduled from follow-on schedule check
[2025-01-11T20:29:03.137+0000] {local_task_job_runner.py:245} INFO - ::endgroup::
