[2025-01-24T11:42:12.590+0000] {local_task_job_runner.py:123} INFO - ::group::Pre task execution logs
[2025-01-24T11:42:12.632+0000] {taskinstance.py:2613} INFO - Dependencies all met for dep_context=non-requeueable deps ti=<TaskInstance: my_first_dbt_dag.run_dbt_model scheduled__2025-01-23T00:00:00+00:00 [queued]>
[2025-01-24T11:42:12.648+0000] {taskinstance.py:2613} INFO - Dependencies all met for dep_context=requeueable deps ti=<TaskInstance: my_first_dbt_dag.run_dbt_model scheduled__2025-01-23T00:00:00+00:00 [queued]>
[2025-01-24T11:42:12.649+0000] {taskinstance.py:2866} INFO - Starting attempt 2 of 2
[2025-01-24T11:42:12.675+0000] {taskinstance.py:2889} INFO - Executing <Task(PythonOperator): run_dbt_model> on 2025-01-23 00:00:00+00:00
[2025-01-24T11:42:12.689+0000] {standard_task_runner.py:104} INFO - Running: ['***', 'tasks', 'run', 'my_first_dbt_dag', 'run_dbt_model', 'scheduled__2025-01-23T00:00:00+00:00', '--job-id', '53', '--raw', '--subdir', 'DAGS_FOLDER/my_first_dbt_dag.py', '--cfg-path', '/tmp/tmpzlv0pzrl']
[2025-01-24T11:42:12.703+0000] {standard_task_runner.py:105} INFO - Job 53: Subtask run_dbt_model
[2025-01-24T11:42:12.720+0000] {logging_mixin.py:190} WARNING - /home/***/.local/lib/python3.12/site-packages/***/task/task_runner/standard_task_runner.py:70 DeprecationWarning: This process (pid=43210) is multi-threaded, use of fork() may lead to deadlocks in the child.
[2025-01-24T11:42:12.721+0000] {standard_task_runner.py:72} INFO - Started process 43214 to run task
[2025-01-24T11:42:12.903+0000] {task_command.py:467} INFO - Running <TaskInstance: my_first_dbt_dag.run_dbt_model scheduled__2025-01-23T00:00:00+00:00 [running]> on host 10a7333bcdf9
[2025-01-24T11:42:13.109+0000] {taskinstance.py:3132} INFO - Exporting env vars: AIRFLOW_CTX_DAG_OWNER='***' AIRFLOW_CTX_DAG_ID='my_first_dbt_dag' AIRFLOW_CTX_TASK_ID='run_dbt_model' AIRFLOW_CTX_EXECUTION_DATE='2025-01-23T00:00:00+00:00' AIRFLOW_CTX_TRY_NUMBER='2' AIRFLOW_CTX_DAG_RUN_ID='scheduled__2025-01-23T00:00:00+00:00'
[2025-01-24T11:42:13.111+0000] {taskinstance.py:731} INFO - ::endgroup::
[2025-01-24T11:42:21.858+0000] {logging_mixin.py:190} INFO - 11:42:18  Running with dbt=1.6.1
11:42:18  Registered adapter: postgres=1.6.1
11:42:20  Found 4 models, 2 seeds, 2 sources, 0 exposures, 0 metrics, 464 macros, 0 groups, 0 semantic models
11:42:20  
11:42:20  Concurrency: 1 threads (target='dev')
11:42:20  
11:42:20  1 of 1 START sql table model jin_schema.my_first_dbt_model ..................... [RUN]
11:42:20  1 of 1 OK created sql table model jin_schema.my_first_dbt_model ................ [SELECT 2 in 0.20s]
11:42:20  
11:42:20  Finished running 1 table model in 0 hours 0 minutes and 0.35 seconds (0.35s).
11:42:20  
11:42:20  Completed successfully
11:42:20  
11:42:20  Done. PASS=1 WARN=0 ERROR=0 SKIP=0 TOTAL=1
[2025-01-24T11:42:21.859+0000] {python.py:240} INFO - Done. Returned value was: None
[2025-01-24T11:42:21.872+0000] {taskinstance.py:340} INFO - ::group::Post task execution logs
[2025-01-24T11:42:21.874+0000] {taskinstance.py:352} INFO - Marking task as SUCCESS. dag_id=my_first_dbt_dag, task_id=run_dbt_model, run_id=scheduled__2025-01-23T00:00:00+00:00, execution_date=20250123T000000, start_date=20250124T114212, end_date=20250124T114221
[2025-01-24T11:42:21.875+0000] {taskinstance.py:1563} INFO - Executing callback at index 0: slack_success_callback
[2025-01-24T11:42:21.876+0000] {taskinstance.py:1567} ERROR - Error in callback at index 0: slack_success_callback
Traceback (most recent call last):
  File "/home/airflow/.local/lib/python3.12/site-packages/airflow/models/taskinstance.py", line 1565, in _run_finished_callback
    callback(context)
  File "/opt/airflow/dags/my_first_dbt_dag.py", line 35, in slack_success_callback
    success_task_alert = SlackWebhookOperator(
                         ^^^^^^^^^^^^^^^^^^^^^
  File "/home/airflow/.local/lib/python3.12/site-packages/airflow/models/baseoperator.py", line 489, in apply_defaults
    raise AirflowException(f"missing keyword argument {missing_args.pop()!r}")
airflow.exceptions.AirflowException: missing keyword argument 'slack_webhook_conn_id'
[2025-01-24T11:42:21.929+0000] {local_task_job_runner.py:266} INFO - Task exited with return code 0
[2025-01-24T11:42:21.986+0000] {taskinstance.py:3895} INFO - 0 downstream tasks scheduled from follow-on schedule check
[2025-01-24T11:42:21.992+0000] {local_task_job_runner.py:245} INFO - ::endgroup::
[2025-01-24T17:37:48.047+0000] {local_task_job_runner.py:123} INFO - ::group::Pre task execution logs
[2025-01-24T17:37:48.073+0000] {taskinstance.py:2613} INFO - Dependencies all met for dep_context=non-requeueable deps ti=<TaskInstance: my_first_dbt_dag.run_dbt_model scheduled__2025-01-23T00:00:00+00:00 [queued]>
[2025-01-24T17:37:48.088+0000] {taskinstance.py:2613} INFO - Dependencies all met for dep_context=requeueable deps ti=<TaskInstance: my_first_dbt_dag.run_dbt_model scheduled__2025-01-23T00:00:00+00:00 [queued]>
[2025-01-24T17:37:48.089+0000] {taskinstance.py:2866} INFO - Starting attempt 2 of 2
[2025-01-24T17:37:48.115+0000] {taskinstance.py:2889} INFO - Executing <Task(PythonOperator): run_dbt_model> on 2025-01-23 00:00:00+00:00
[2025-01-24T17:37:48.130+0000] {standard_task_runner.py:104} INFO - Running: ['***', 'tasks', 'run', 'my_first_dbt_dag', 'run_dbt_model', 'scheduled__2025-01-23T00:00:00+00:00', '--job-id', '8', '--raw', '--subdir', 'DAGS_FOLDER/my_first_dbt_dag.py', '--cfg-path', '/tmp/tmp6gk_8wfp']
[2025-01-24T17:37:48.147+0000] {standard_task_runner.py:105} INFO - Job 8: Subtask run_dbt_model
[2025-01-24T17:37:48.159+0000] {logging_mixin.py:190} WARNING - /home/***/.local/lib/python3.12/site-packages/***/task/task_runner/standard_task_runner.py:70 DeprecationWarning: This process (pid=372) is multi-threaded, use of fork() may lead to deadlocks in the child.
[2025-01-24T17:37:48.163+0000] {standard_task_runner.py:72} INFO - Started process 373 to run task
[2025-01-24T17:37:48.271+0000] {task_command.py:467} INFO - Running <TaskInstance: my_first_dbt_dag.run_dbt_model scheduled__2025-01-23T00:00:00+00:00 [running]> on host 77d03311c267
[2025-01-24T17:37:48.414+0000] {taskinstance.py:3132} INFO - Exporting env vars: AIRFLOW_CTX_DAG_OWNER='***' AIRFLOW_CTX_DAG_ID='my_first_dbt_dag' AIRFLOW_CTX_TASK_ID='run_dbt_model' AIRFLOW_CTX_EXECUTION_DATE='2025-01-23T00:00:00+00:00' AIRFLOW_CTX_TRY_NUMBER='2' AIRFLOW_CTX_DAG_RUN_ID='scheduled__2025-01-23T00:00:00+00:00'
[2025-01-24T17:37:48.416+0000] {taskinstance.py:731} INFO - ::endgroup::
[2025-01-24T17:37:56.223+0000] {logging_mixin.py:190} INFO - Error during DBT run: 
[2025-01-24T17:37:56.224+0000] {taskinstance.py:3311} ERROR - Task failed with exception
Traceback (most recent call last):
  File "/home/airflow/.local/lib/python3.12/site-packages/airflow/models/taskinstance.py", line 767, in _execute_task
    result = _execute_callable(context=context, **execute_callable_kwargs)
             ^^^^^^^^^^^^^^^^^^^^^^^^^^^^^^^^^^^^^^^^^^^^^^^^^^^^^^^^^^^^^
  File "/home/airflow/.local/lib/python3.12/site-packages/airflow/models/taskinstance.py", line 733, in _execute_callable
    return ExecutionCallableRunner(
           ^^^^^^^^^^^^^^^^^^^^^^^^
  File "/home/airflow/.local/lib/python3.12/site-packages/airflow/utils/operator_helpers.py", line 252, in run
    return self.func(*args, **kwargs)
           ^^^^^^^^^^^^^^^^^^^^^^^^^^
  File "/home/airflow/.local/lib/python3.12/site-packages/airflow/models/baseoperator.py", line 422, in wrapper
    return func(self, *args, **kwargs)
           ^^^^^^^^^^^^^^^^^^^^^^^^^^^
  File "/home/airflow/.local/lib/python3.12/site-packages/airflow/operators/python.py", line 238, in execute
    return_value = self.execute_callable()
                   ^^^^^^^^^^^^^^^^^^^^^^^
  File "/home/airflow/.local/lib/python3.12/site-packages/airflow/operators/python.py", line 256, in execute_callable
    return runner.run(*self.op_args, **self.op_kwargs)
           ^^^^^^^^^^^^^^^^^^^^^^^^^^^^^^^^^^^^^^^^^^^
  File "/home/airflow/.local/lib/python3.12/site-packages/airflow/utils/operator_helpers.py", line 252, in run
    return self.func(*args, **kwargs)
           ^^^^^^^^^^^^^^^^^^^^^^^^^^
  File "/opt/airflow/dags/my_first_dbt_dag.py", line 54, in run_dbt_model
    raise e  # Raise again to make sure the task fails correctly
    ^^^^^^^
  File "/opt/airflow/dags/my_first_dbt_dag.py", line 45, in run_dbt_model
    result = subprocess.run(
             ^^^^^^^^^^^^^^^
  File "/usr/local/lib/python3.12/subprocess.py", line 571, in run
    raise CalledProcessError(retcode, process.args,
subprocess.CalledProcessError: Command '['dbt', 'run', '--project-dir', '/opt/dbt-project', '--profiles-dir', '/opt/dbt-project', '--select', 'my_first_dbt_model']' returned non-zero exit status 2.
[2025-01-24T17:37:56.239+0000] {taskinstance.py:1225} INFO - Marking task as FAILED. dag_id=my_first_dbt_dag, task_id=run_dbt_model, run_id=scheduled__2025-01-23T00:00:00+00:00, execution_date=20250123T000000, start_date=20250124T173748, end_date=20250124T173756
[2025-01-24T17:37:56.240+0000] {taskinstance.py:1563} INFO - Executing callback at index 0: slack_failure_callback
[2025-01-24T17:37:56.241+0000] {taskinstance.py:1567} ERROR - Error in callback at index 0: slack_failure_callback
Traceback (most recent call last):
  File "/home/airflow/.local/lib/python3.12/site-packages/airflow/models/taskinstance.py", line 273, in _run_raw_task
    TaskInstance._execute_task_with_callbacks(
  File "/home/airflow/.local/lib/python3.12/site-packages/airflow/models/taskinstance.py", line 3159, in _execute_task_with_callbacks
    result = self._execute_task(context, task_orig)
             ^^^^^^^^^^^^^^^^^^^^^^^^^^^^^^^^^^^^^^
  File "/home/airflow/.local/lib/python3.12/site-packages/airflow/models/taskinstance.py", line 3183, in _execute_task
    return _execute_task(self, context, task_orig)
           ^^^^^^^^^^^^^^^^^^^^^^^^^^^^^^^^^^^^^^^
  File "/home/airflow/.local/lib/python3.12/site-packages/airflow/models/taskinstance.py", line 767, in _execute_task
    result = _execute_callable(context=context, **execute_callable_kwargs)
             ^^^^^^^^^^^^^^^^^^^^^^^^^^^^^^^^^^^^^^^^^^^^^^^^^^^^^^^^^^^^^
  File "/home/airflow/.local/lib/python3.12/site-packages/airflow/models/taskinstance.py", line 733, in _execute_callable
    return ExecutionCallableRunner(
           ^^^^^^^^^^^^^^^^^^^^^^^^
  File "/home/airflow/.local/lib/python3.12/site-packages/airflow/utils/operator_helpers.py", line 252, in run
    return self.func(*args, **kwargs)
           ^^^^^^^^^^^^^^^^^^^^^^^^^^
  File "/home/airflow/.local/lib/python3.12/site-packages/airflow/models/baseoperator.py", line 422, in wrapper
    return func(self, *args, **kwargs)
           ^^^^^^^^^^^^^^^^^^^^^^^^^^^
  File "/home/airflow/.local/lib/python3.12/site-packages/airflow/operators/python.py", line 238, in execute
    return_value = self.execute_callable()
                   ^^^^^^^^^^^^^^^^^^^^^^^
  File "/home/airflow/.local/lib/python3.12/site-packages/airflow/operators/python.py", line 256, in execute_callable
    return runner.run(*self.op_args, **self.op_kwargs)
           ^^^^^^^^^^^^^^^^^^^^^^^^^^^^^^^^^^^^^^^^^^^
  File "/home/airflow/.local/lib/python3.12/site-packages/airflow/utils/operator_helpers.py", line 252, in run
    return self.func(*args, **kwargs)
           ^^^^^^^^^^^^^^^^^^^^^^^^^^
  File "/opt/airflow/dags/my_first_dbt_dag.py", line 54, in run_dbt_model
    raise e  # Raise again to make sure the task fails correctly
    ^^^^^^^
  File "/opt/airflow/dags/my_first_dbt_dag.py", line 45, in run_dbt_model
    result = subprocess.run(
             ^^^^^^^^^^^^^^^
  File "/usr/local/lib/python3.12/subprocess.py", line 571, in run
    raise CalledProcessError(retcode, process.args,
subprocess.CalledProcessError: Command '['dbt', 'run', '--project-dir', '/opt/dbt-project', '--profiles-dir', '/opt/dbt-project', '--select', 'my_first_dbt_model']' returned non-zero exit status 2.

During handling of the above exception, another exception occurred:

Traceback (most recent call last):
  File "/home/airflow/.local/lib/python3.12/site-packages/airflow/models/taskinstance.py", line 1565, in _run_finished_callback
    callback(context)
  File "/opt/airflow/dags/my_first_dbt_dag.py", line 19, in slack_failure_callback
    failed_task_alert = SlackWebhookOperator(
                        ^^^^^^^^^^^^^^^^^^^^^
  File "/home/airflow/.local/lib/python3.12/site-packages/airflow/models/baseoperator.py", line 489, in apply_defaults
    raise AirflowException(f"missing keyword argument {missing_args.pop()!r}")
airflow.exceptions.AirflowException: missing keyword argument 'slack_webhook_conn_id'
[2025-01-24T17:37:56.256+0000] {taskinstance.py:340} INFO - ::group::Post task execution logs
[2025-01-24T17:37:56.256+0000] {standard_task_runner.py:124} ERROR - Failed to execute job 8 for task run_dbt_model (Command '['dbt', 'run', '--project-dir', '/opt/dbt-project', '--profiles-dir', '/opt/dbt-project', '--select', 'my_first_dbt_model']' returned non-zero exit status 2.; 373)
Traceback (most recent call last):
  File "/home/airflow/.local/lib/python3.12/site-packages/airflow/task/task_runner/standard_task_runner.py", line 117, in _start_by_fork
    ret = args.func(args, dag=self.dag)
          ^^^^^^^^^^^^^^^^^^^^^^^^^^^^^
  File "/home/airflow/.local/lib/python3.12/site-packages/airflow/cli/cli_config.py", line 49, in command
    return func(*args, **kwargs)
           ^^^^^^^^^^^^^^^^^^^^^
  File "/home/airflow/.local/lib/python3.12/site-packages/airflow/utils/cli.py", line 116, in wrapper
    return f(*args, **kwargs)
           ^^^^^^^^^^^^^^^^^^
  File "/home/airflow/.local/lib/python3.12/site-packages/airflow/cli/commands/task_command.py", line 483, in task_run
    task_return_code = _run_task_by_selected_method(args, _dag, ti)
                       ^^^^^^^^^^^^^^^^^^^^^^^^^^^^^^^^^^^^^^^^^^^^
  File "/home/airflow/.local/lib/python3.12/site-packages/airflow/cli/commands/task_command.py", line 256, in _run_task_by_selected_method
    return _run_raw_task(args, ti)
           ^^^^^^^^^^^^^^^^^^^^^^^
  File "/home/airflow/.local/lib/python3.12/site-packages/airflow/cli/commands/task_command.py", line 341, in _run_raw_task
    return ti._run_raw_task(
           ^^^^^^^^^^^^^^^^^
  File "/home/airflow/.local/lib/python3.12/site-packages/airflow/utils/session.py", line 97, in wrapper
    return func(*args, session=session, **kwargs)
           ^^^^^^^^^^^^^^^^^^^^^^^^^^^^^^^^^^^^^^
  File "/home/airflow/.local/lib/python3.12/site-packages/airflow/models/taskinstance.py", line 3005, in _run_raw_task
    return _run_raw_task(
           ^^^^^^^^^^^^^^
  File "/home/airflow/.local/lib/python3.12/site-packages/airflow/models/taskinstance.py", line 273, in _run_raw_task
    TaskInstance._execute_task_with_callbacks(
  File "/home/airflow/.local/lib/python3.12/site-packages/airflow/models/taskinstance.py", line 3159, in _execute_task_with_callbacks
    result = self._execute_task(context, task_orig)
             ^^^^^^^^^^^^^^^^^^^^^^^^^^^^^^^^^^^^^^
  File "/home/airflow/.local/lib/python3.12/site-packages/airflow/models/taskinstance.py", line 3183, in _execute_task
    return _execute_task(self, context, task_orig)
           ^^^^^^^^^^^^^^^^^^^^^^^^^^^^^^^^^^^^^^^
  File "/home/airflow/.local/lib/python3.12/site-packages/airflow/models/taskinstance.py", line 767, in _execute_task
    result = _execute_callable(context=context, **execute_callable_kwargs)
             ^^^^^^^^^^^^^^^^^^^^^^^^^^^^^^^^^^^^^^^^^^^^^^^^^^^^^^^^^^^^^
  File "/home/airflow/.local/lib/python3.12/site-packages/airflow/models/taskinstance.py", line 733, in _execute_callable
    return ExecutionCallableRunner(
           ^^^^^^^^^^^^^^^^^^^^^^^^
  File "/home/airflow/.local/lib/python3.12/site-packages/airflow/utils/operator_helpers.py", line 252, in run
    return self.func(*args, **kwargs)
           ^^^^^^^^^^^^^^^^^^^^^^^^^^
  File "/home/airflow/.local/lib/python3.12/site-packages/airflow/models/baseoperator.py", line 422, in wrapper
    return func(self, *args, **kwargs)
           ^^^^^^^^^^^^^^^^^^^^^^^^^^^
  File "/home/airflow/.local/lib/python3.12/site-packages/airflow/operators/python.py", line 238, in execute
    return_value = self.execute_callable()
                   ^^^^^^^^^^^^^^^^^^^^^^^
  File "/home/airflow/.local/lib/python3.12/site-packages/airflow/operators/python.py", line 256, in execute_callable
    return runner.run(*self.op_args, **self.op_kwargs)
           ^^^^^^^^^^^^^^^^^^^^^^^^^^^^^^^^^^^^^^^^^^^
  File "/home/airflow/.local/lib/python3.12/site-packages/airflow/utils/operator_helpers.py", line 252, in run
    return self.func(*args, **kwargs)
           ^^^^^^^^^^^^^^^^^^^^^^^^^^
  File "/opt/airflow/dags/my_first_dbt_dag.py", line 54, in run_dbt_model
    raise e  # Raise again to make sure the task fails correctly
    ^^^^^^^
  File "/opt/airflow/dags/my_first_dbt_dag.py", line 45, in run_dbt_model
    result = subprocess.run(
             ^^^^^^^^^^^^^^^
  File "/usr/local/lib/python3.12/subprocess.py", line 571, in run
    raise CalledProcessError(retcode, process.args,
subprocess.CalledProcessError: Command '['dbt', 'run', '--project-dir', '/opt/dbt-project', '--profiles-dir', '/opt/dbt-project', '--select', 'my_first_dbt_model']' returned non-zero exit status 2.
[2025-01-24T17:37:56.293+0000] {local_task_job_runner.py:266} INFO - Task exited with return code 1
[2025-01-24T17:37:56.306+0000] {taskinstance.py:3895} INFO - 0 downstream tasks scheduled from follow-on schedule check
[2025-01-24T17:37:56.308+0000] {local_task_job_runner.py:245} INFO - ::endgroup::
[2025-01-24T18:26:20.833+0000] {local_task_job_runner.py:123} INFO - ::group::Pre task execution logs
[2025-01-24T18:26:20.851+0000] {taskinstance.py:2613} INFO - Dependencies all met for dep_context=non-requeueable deps ti=<TaskInstance: my_first_dbt_dag.run_dbt_model scheduled__2025-01-23T00:00:00+00:00 [queued]>
[2025-01-24T18:26:20.862+0000] {taskinstance.py:2613} INFO - Dependencies all met for dep_context=requeueable deps ti=<TaskInstance: my_first_dbt_dag.run_dbt_model scheduled__2025-01-23T00:00:00+00:00 [queued]>
[2025-01-24T18:26:20.863+0000] {taskinstance.py:2866} INFO - Starting attempt 2 of 2
[2025-01-24T18:26:20.886+0000] {taskinstance.py:2889} INFO - Executing <Task(PythonOperator): run_dbt_model> on 2025-01-23 00:00:00+00:00
[2025-01-24T18:26:20.894+0000] {standard_task_runner.py:104} INFO - Running: ['***', 'tasks', 'run', 'my_first_dbt_dag', 'run_dbt_model', 'scheduled__2025-01-23T00:00:00+00:00', '--job-id', '6', '--raw', '--subdir', 'DAGS_FOLDER/my_first_dbt_dag.py', '--cfg-path', '/tmp/tmpo2qvl7lh']
[2025-01-24T18:26:20.897+0000] {standard_task_runner.py:105} INFO - Job 6: Subtask run_dbt_model
[2025-01-24T18:26:20.901+0000] {logging_mixin.py:190} WARNING - /home/***/.local/lib/python3.12/site-packages/***/task/task_runner/standard_task_runner.py:70 DeprecationWarning: This process (pid=422) is multi-threaded, use of fork() may lead to deadlocks in the child.
[2025-01-24T18:26:20.903+0000] {standard_task_runner.py:72} INFO - Started process 423 to run task
[2025-01-24T18:26:20.952+0000] {task_command.py:467} INFO - Running <TaskInstance: my_first_dbt_dag.run_dbt_model scheduled__2025-01-23T00:00:00+00:00 [running]> on host b4a1ef9b7f63
[2025-01-24T18:26:21.049+0000] {taskinstance.py:3132} INFO - Exporting env vars: AIRFLOW_CTX_DAG_OWNER='***' AIRFLOW_CTX_DAG_ID='my_first_dbt_dag' AIRFLOW_CTX_TASK_ID='run_dbt_model' AIRFLOW_CTX_EXECUTION_DATE='2025-01-23T00:00:00+00:00' AIRFLOW_CTX_TRY_NUMBER='2' AIRFLOW_CTX_DAG_RUN_ID='scheduled__2025-01-23T00:00:00+00:00'
[2025-01-24T18:26:21.050+0000] {taskinstance.py:731} INFO - ::endgroup::
[2025-01-24T18:26:25.570+0000] {logging_mixin.py:190} INFO - 18:26:23  Running with dbt=1.6.1
18:26:23  Registered adapter: postgres=1.6.1
18:26:24  Found 4 models, 2 sources, 0 exposures, 0 metrics, 464 macros, 0 groups, 0 semantic models
18:26:24  
18:26:24  Concurrency: 1 threads (target='dev')
18:26:24  
18:26:24  1 of 1 START sql table model jin_schema.my_first_dbt_model ..................... [RUN]
18:26:24  1 of 1 OK created sql table model jin_schema.my_first_dbt_model ................ [SELECT 2 in 0.15s]
18:26:24  
18:26:24  Finished running 1 table model in 0 hours 0 minutes and 0.26 seconds (0.26s).
18:26:24  
18:26:24  Completed successfully
18:26:24  
18:26:24  Done. PASS=1 WARN=0 ERROR=0 SKIP=0 TOTAL=1
[2025-01-24T18:26:25.571+0000] {python.py:240} INFO - Done. Returned value was: None
[2025-01-24T18:26:25.582+0000] {taskinstance.py:340} INFO - ::group::Post task execution logs
[2025-01-24T18:26:25.583+0000] {taskinstance.py:352} INFO - Marking task as SUCCESS. dag_id=my_first_dbt_dag, task_id=run_dbt_model, run_id=scheduled__2025-01-23T00:00:00+00:00, execution_date=20250123T000000, start_date=20250124T182620, end_date=20250124T182625
[2025-01-24T18:26:25.584+0000] {taskinstance.py:1563} INFO - Executing callback at index 0: slack_success_callback
[2025-01-24T18:26:25.584+0000] {taskinstance.py:1567} ERROR - Error in callback at index 0: slack_success_callback
Traceback (most recent call last):
  File "/home/airflow/.local/lib/python3.12/site-packages/airflow/models/taskinstance.py", line 1565, in _run_finished_callback
    callback(context)
  File "/opt/airflow/dags/my_first_dbt_dag.py", line 35, in slack_success_callback
    success_task_alert = SlackWebhookOperator(
                         ^^^^^^^^^^^^^^^^^^^^^
  File "/home/airflow/.local/lib/python3.12/site-packages/airflow/models/baseoperator.py", line 489, in apply_defaults
    raise AirflowException(f"missing keyword argument {missing_args.pop()!r}")
airflow.exceptions.AirflowException: missing keyword argument 'slack_webhook_conn_id'
[2025-01-24T18:26:25.660+0000] {local_task_job_runner.py:266} INFO - Task exited with return code 0
[2025-01-24T18:26:25.684+0000] {taskinstance.py:3895} INFO - 0 downstream tasks scheduled from follow-on schedule check
[2025-01-24T18:26:25.687+0000] {local_task_job_runner.py:245} INFO - ::endgroup::
