[2025-01-12T13:12:16.864+0000] {local_task_job_runner.py:123} INFO - ::group::Pre task execution logs
[2025-01-12T13:12:16.882+0000] {taskinstance.py:2613} INFO - Dependencies all met for dep_context=non-requeueable deps ti=<TaskInstance: my_second_dbt_dag.run_dbt_model manual__2025-01-12T13:12:16.351724+00:00 [queued]>
[2025-01-12T13:12:16.891+0000] {taskinstance.py:2613} INFO - Dependencies all met for dep_context=requeueable deps ti=<TaskInstance: my_second_dbt_dag.run_dbt_model manual__2025-01-12T13:12:16.351724+00:00 [queued]>
[2025-01-12T13:12:16.892+0000] {taskinstance.py:2866} INFO - Starting attempt 1 of 2
[2025-01-12T13:12:16.906+0000] {taskinstance.py:2889} INFO - Executing <Task(PythonOperator): run_dbt_model> on 2025-01-12 13:12:16.351724+00:00
[2025-01-12T13:12:16.914+0000] {standard_task_runner.py:104} INFO - Running: ['***', 'tasks', 'run', 'my_second_dbt_dag', 'run_dbt_model', 'manual__2025-01-12T13:12:16.351724+00:00', '--job-id', '9', '--raw', '--subdir', 'DAGS_FOLDER/my_second_dbt_dag.py', '--cfg-path', '/tmp/tmpzk0q5wz5']
[2025-01-12T13:12:16.917+0000] {standard_task_runner.py:105} INFO - Job 9: Subtask run_dbt_model
[2025-01-12T13:12:16.917+0000] {logging_mixin.py:190} WARNING - /home/***/.local/lib/python3.12/site-packages/***/task/task_runner/standard_task_runner.py:70 DeprecationWarning: This process (pid=362) is multi-threaded, use of fork() may lead to deadlocks in the child.
[2025-01-12T13:12:16.918+0000] {standard_task_runner.py:72} INFO - Started process 363 to run task
[2025-01-12T13:12:16.958+0000] {task_command.py:467} INFO - Running <TaskInstance: my_second_dbt_dag.run_dbt_model manual__2025-01-12T13:12:16.351724+00:00 [running]> on host 0c3be2a2e4e9
[2025-01-12T13:12:17.027+0000] {taskinstance.py:3132} INFO - Exporting env vars: AIRFLOW_CTX_DAG_OWNER='***' AIRFLOW_CTX_DAG_ID='my_second_dbt_dag' AIRFLOW_CTX_TASK_ID='run_dbt_model' AIRFLOW_CTX_EXECUTION_DATE='2025-01-12T13:12:16.351724+00:00' AIRFLOW_CTX_TRY_NUMBER='1' AIRFLOW_CTX_DAG_RUN_ID='manual__2025-01-12T13:12:16.351724+00:00'
[2025-01-12T13:12:17.028+0000] {taskinstance.py:731} INFO - ::endgroup::
[2025-01-12T13:12:17.355+0000] {logging_mixin.py:190} INFO - Error during DBT run: Traceback (most recent call last):
  File "/home/***/.local/bin/dbt", line 5, in <module>
    from dbt.cli.main import cli
  File "/home/***/.local/lib/python3.12/site-packages/dbt/cli/__init__.py", line 1, in <module>
    from .main import cli as dbt_cli  # noqa
    ^^^^^^^^^^^^^^^^^^^^^^^^^^^^^^^^
  File "/home/***/.local/lib/python3.12/site-packages/dbt/cli/main.py", line 11, in <module>
    from dbt.adapters.factory import register_adapter
  File "/home/***/.local/lib/python3.12/site-packages/dbt/adapters/factory.py", line 9, in <module>
    from dbt_common.events.functions import fire_event
  File "/home/***/.local/lib/python3.12/site-packages/dbt_common/events/__init__.py", line 1, in <module>
    from dbt_common.events.base_types import EventLevel
  File "/home/***/.local/lib/python3.12/site-packages/dbt_common/events/base_types.py", line 4, in <module>
    from dbt_common.events import types_pb2
  File "/home/***/.local/lib/python3.12/site-packages/dbt_common/events/types_pb2.py", line 9, in <module>
    from google.protobuf import runtime_version as _runtime_version
ImportError: cannot import name 'runtime_version' from 'google.protobuf' (/home/***/.local/lib/python3.12/site-packages/google/protobuf/__init__.py)
[2025-01-12T13:12:17.356+0000] {taskinstance.py:3311} ERROR - Task failed with exception
Traceback (most recent call last):
  File "/home/airflow/.local/lib/python3.12/site-packages/airflow/models/taskinstance.py", line 767, in _execute_task
    result = _execute_callable(context=context, **execute_callable_kwargs)
             ^^^^^^^^^^^^^^^^^^^^^^^^^^^^^^^^^^^^^^^^^^^^^^^^^^^^^^^^^^^^^
  File "/home/airflow/.local/lib/python3.12/site-packages/airflow/models/taskinstance.py", line 733, in _execute_callable
    return ExecutionCallableRunner(
           ^^^^^^^^^^^^^^^^^^^^^^^^
  File "/home/airflow/.local/lib/python3.12/site-packages/airflow/utils/operator_helpers.py", line 252, in run
    return self.func(*args, **kwargs)
           ^^^^^^^^^^^^^^^^^^^^^^^^^^
  File "/home/airflow/.local/lib/python3.12/site-packages/airflow/models/baseoperator.py", line 422, in wrapper
    return func(self, *args, **kwargs)
           ^^^^^^^^^^^^^^^^^^^^^^^^^^^
  File "/home/airflow/.local/lib/python3.12/site-packages/airflow/operators/python.py", line 238, in execute
    return_value = self.execute_callable()
                   ^^^^^^^^^^^^^^^^^^^^^^^
  File "/home/airflow/.local/lib/python3.12/site-packages/airflow/operators/python.py", line 256, in execute_callable
    return runner.run(*self.op_args, **self.op_kwargs)
           ^^^^^^^^^^^^^^^^^^^^^^^^^^^^^^^^^^^^^^^^^^^
  File "/home/airflow/.local/lib/python3.12/site-packages/airflow/utils/operator_helpers.py", line 252, in run
    return self.func(*args, **kwargs)
           ^^^^^^^^^^^^^^^^^^^^^^^^^^
  File "/opt/airflow/dags/my_second_dbt_dag.py", line 17, in run_dbt_model
    raise e  # Raise again to make sure the task fails correctly
    ^^^^^^^
  File "/opt/airflow/dags/my_second_dbt_dag.py", line 8, in run_dbt_model
    result = subprocess.run(
             ^^^^^^^^^^^^^^^
  File "/usr/local/lib/python3.12/subprocess.py", line 571, in run
    raise CalledProcessError(retcode, process.args,
subprocess.CalledProcessError: Command '['dbt', 'run', '--project-dir', '/opt/dbt-project', '--profiles-dir', '/opt/dbt-project']' returned non-zero exit status 1.
[2025-01-12T13:12:17.370+0000] {taskinstance.py:1225} INFO - Marking task as UP_FOR_RETRY. dag_id=my_second_dbt_dag, task_id=run_dbt_model, run_id=manual__2025-01-12T13:12:16.351724+00:00, execution_date=20250112T131216, start_date=20250112T131216, end_date=20250112T131217
[2025-01-12T13:12:17.381+0000] {taskinstance.py:340} INFO - ::group::Post task execution logs
[2025-01-12T13:12:17.382+0000] {standard_task_runner.py:124} ERROR - Failed to execute job 9 for task run_dbt_model (Command '['dbt', 'run', '--project-dir', '/opt/dbt-project', '--profiles-dir', '/opt/dbt-project']' returned non-zero exit status 1.; 363)
Traceback (most recent call last):
  File "/home/airflow/.local/lib/python3.12/site-packages/airflow/task/task_runner/standard_task_runner.py", line 117, in _start_by_fork
    ret = args.func(args, dag=self.dag)
          ^^^^^^^^^^^^^^^^^^^^^^^^^^^^^
  File "/home/airflow/.local/lib/python3.12/site-packages/airflow/cli/cli_config.py", line 49, in command
    return func(*args, **kwargs)
           ^^^^^^^^^^^^^^^^^^^^^
  File "/home/airflow/.local/lib/python3.12/site-packages/airflow/utils/cli.py", line 116, in wrapper
    return f(*args, **kwargs)
           ^^^^^^^^^^^^^^^^^^
  File "/home/airflow/.local/lib/python3.12/site-packages/airflow/cli/commands/task_command.py", line 483, in task_run
    task_return_code = _run_task_by_selected_method(args, _dag, ti)
                       ^^^^^^^^^^^^^^^^^^^^^^^^^^^^^^^^^^^^^^^^^^^^
  File "/home/airflow/.local/lib/python3.12/site-packages/airflow/cli/commands/task_command.py", line 256, in _run_task_by_selected_method
    return _run_raw_task(args, ti)
           ^^^^^^^^^^^^^^^^^^^^^^^
  File "/home/airflow/.local/lib/python3.12/site-packages/airflow/cli/commands/task_command.py", line 341, in _run_raw_task
    return ti._run_raw_task(
           ^^^^^^^^^^^^^^^^^
  File "/home/airflow/.local/lib/python3.12/site-packages/airflow/utils/session.py", line 97, in wrapper
    return func(*args, session=session, **kwargs)
           ^^^^^^^^^^^^^^^^^^^^^^^^^^^^^^^^^^^^^^
  File "/home/airflow/.local/lib/python3.12/site-packages/airflow/models/taskinstance.py", line 3005, in _run_raw_task
    return _run_raw_task(
           ^^^^^^^^^^^^^^
  File "/home/airflow/.local/lib/python3.12/site-packages/airflow/models/taskinstance.py", line 273, in _run_raw_task
    TaskInstance._execute_task_with_callbacks(
  File "/home/airflow/.local/lib/python3.12/site-packages/airflow/models/taskinstance.py", line 3159, in _execute_task_with_callbacks
    result = self._execute_task(context, task_orig)
             ^^^^^^^^^^^^^^^^^^^^^^^^^^^^^^^^^^^^^^
  File "/home/airflow/.local/lib/python3.12/site-packages/airflow/models/taskinstance.py", line 3183, in _execute_task
    return _execute_task(self, context, task_orig)
           ^^^^^^^^^^^^^^^^^^^^^^^^^^^^^^^^^^^^^^^
  File "/home/airflow/.local/lib/python3.12/site-packages/airflow/models/taskinstance.py", line 767, in _execute_task
    result = _execute_callable(context=context, **execute_callable_kwargs)
             ^^^^^^^^^^^^^^^^^^^^^^^^^^^^^^^^^^^^^^^^^^^^^^^^^^^^^^^^^^^^^
  File "/home/airflow/.local/lib/python3.12/site-packages/airflow/models/taskinstance.py", line 733, in _execute_callable
    return ExecutionCallableRunner(
           ^^^^^^^^^^^^^^^^^^^^^^^^
  File "/home/airflow/.local/lib/python3.12/site-packages/airflow/utils/operator_helpers.py", line 252, in run
    return self.func(*args, **kwargs)
           ^^^^^^^^^^^^^^^^^^^^^^^^^^
  File "/home/airflow/.local/lib/python3.12/site-packages/airflow/models/baseoperator.py", line 422, in wrapper
    return func(self, *args, **kwargs)
           ^^^^^^^^^^^^^^^^^^^^^^^^^^^
  File "/home/airflow/.local/lib/python3.12/site-packages/airflow/operators/python.py", line 238, in execute
    return_value = self.execute_callable()
                   ^^^^^^^^^^^^^^^^^^^^^^^
  File "/home/airflow/.local/lib/python3.12/site-packages/airflow/operators/python.py", line 256, in execute_callable
    return runner.run(*self.op_args, **self.op_kwargs)
           ^^^^^^^^^^^^^^^^^^^^^^^^^^^^^^^^^^^^^^^^^^^
  File "/home/airflow/.local/lib/python3.12/site-packages/airflow/utils/operator_helpers.py", line 252, in run
    return self.func(*args, **kwargs)
           ^^^^^^^^^^^^^^^^^^^^^^^^^^
  File "/opt/airflow/dags/my_second_dbt_dag.py", line 17, in run_dbt_model
    raise e  # Raise again to make sure the task fails correctly
    ^^^^^^^
  File "/opt/airflow/dags/my_second_dbt_dag.py", line 8, in run_dbt_model
    result = subprocess.run(
             ^^^^^^^^^^^^^^^
  File "/usr/local/lib/python3.12/subprocess.py", line 571, in run
    raise CalledProcessError(retcode, process.args,
subprocess.CalledProcessError: Command '['dbt', 'run', '--project-dir', '/opt/dbt-project', '--profiles-dir', '/opt/dbt-project']' returned non-zero exit status 1.
[2025-01-12T13:12:17.415+0000] {local_task_job_runner.py:266} INFO - Task exited with return code 1
[2025-01-12T13:12:17.439+0000] {taskinstance.py:3895} INFO - 0 downstream tasks scheduled from follow-on schedule check
[2025-01-12T13:12:17.442+0000] {local_task_job_runner.py:245} INFO - ::endgroup::
