[2025-01-15T20:47:38.673+0000] {local_task_job_runner.py:123} INFO - ::group::Pre task execution logs
[2025-01-15T20:47:38.980+0000] {taskinstance.py:2613} INFO - Dependencies all met for dep_context=non-requeueable deps ti=<TaskInstance: my_first_dbt_dag.run_dbt_model scheduled__2025-01-14T00:00:00+00:00 [queued]>
[2025-01-15T20:47:39.065+0000] {taskinstance.py:2613} INFO - Dependencies all met for dep_context=requeueable deps ti=<TaskInstance: my_first_dbt_dag.run_dbt_model scheduled__2025-01-14T00:00:00+00:00 [queued]>
[2025-01-15T20:47:39.077+0000] {taskinstance.py:2866} INFO - Starting attempt 1 of 2
[2025-01-15T20:47:39.897+0000] {taskinstance.py:2889} INFO - Executing <Task(PythonOperator): run_dbt_model> on 2025-01-14 00:00:00+00:00
[2025-01-15T20:47:40.816+0000] {standard_task_runner.py:104} INFO - Running: ['***', 'tasks', 'run', 'my_first_dbt_dag', 'run_dbt_model', 'scheduled__2025-01-14T00:00:00+00:00', '--job-id', '24', '--raw', '--subdir', 'DAGS_FOLDER/my_first_dbt_dag.py', '--cfg-path', '/tmp/tmpxv9y_x7d']
[2025-01-15T20:47:41.023+0000] {standard_task_runner.py:105} INFO - Job 24: Subtask run_dbt_model
[2025-01-15T20:47:40.901+0000] {logging_mixin.py:190} WARNING - /home/***/.local/lib/python3.12/site-packages/***/task/task_runner/standard_task_runner.py:70 DeprecationWarning: This process (pid=7448) is multi-threaded, use of fork() may lead to deadlocks in the child.
[2025-01-15T20:47:41.039+0000] {standard_task_runner.py:72} INFO - Started process 7457 to run task
[2025-01-15T20:47:42.473+0000] {task_command.py:467} INFO - Running <TaskInstance: my_first_dbt_dag.run_dbt_model scheduled__2025-01-14T00:00:00+00:00 [running]> on host 10a7333bcdf9
[2025-01-15T20:47:42.996+0000] {taskinstance.py:3132} INFO - Exporting env vars: AIRFLOW_CTX_DAG_OWNER='***' AIRFLOW_CTX_DAG_ID='my_first_dbt_dag' AIRFLOW_CTX_TASK_ID='run_dbt_model' AIRFLOW_CTX_EXECUTION_DATE='2025-01-14T00:00:00+00:00' AIRFLOW_CTX_TRY_NUMBER='1' AIRFLOW_CTX_DAG_RUN_ID='scheduled__2025-01-14T00:00:00+00:00'
[2025-01-15T20:47:43.056+0000] {taskinstance.py:731} INFO - ::endgroup::
[2025-01-15T20:48:05.754+0000] {logging_mixin.py:190} INFO - Error during DBT run: 
[2025-01-15T20:48:05.790+0000] {taskinstance.py:3311} ERROR - Task failed with exception
Traceback (most recent call last):
  File "/home/airflow/.local/lib/python3.12/site-packages/airflow/models/taskinstance.py", line 767, in _execute_task
    result = _execute_callable(context=context, **execute_callable_kwargs)
             ^^^^^^^^^^^^^^^^^^^^^^^^^^^^^^^^^^^^^^^^^^^^^^^^^^^^^^^^^^^^^
  File "/home/airflow/.local/lib/python3.12/site-packages/airflow/models/taskinstance.py", line 733, in _execute_callable
    return ExecutionCallableRunner(
           ^^^^^^^^^^^^^^^^^^^^^^^^
  File "/home/airflow/.local/lib/python3.12/site-packages/airflow/utils/operator_helpers.py", line 252, in run
    return self.func(*args, **kwargs)
           ^^^^^^^^^^^^^^^^^^^^^^^^^^
  File "/home/airflow/.local/lib/python3.12/site-packages/airflow/models/baseoperator.py", line 422, in wrapper
    return func(self, *args, **kwargs)
           ^^^^^^^^^^^^^^^^^^^^^^^^^^^
  File "/home/airflow/.local/lib/python3.12/site-packages/airflow/operators/python.py", line 238, in execute
    return_value = self.execute_callable()
                   ^^^^^^^^^^^^^^^^^^^^^^^
  File "/home/airflow/.local/lib/python3.12/site-packages/airflow/operators/python.py", line 256, in execute_callable
    return runner.run(*self.op_args, **self.op_kwargs)
           ^^^^^^^^^^^^^^^^^^^^^^^^^^^^^^^^^^^^^^^^^^^
  File "/home/airflow/.local/lib/python3.12/site-packages/airflow/utils/operator_helpers.py", line 252, in run
    return self.func(*args, **kwargs)
           ^^^^^^^^^^^^^^^^^^^^^^^^^^
  File "/opt/airflow/dags/my_first_dbt_dag.py", line 54, in run_dbt_model
    raise e  # Raise again to make sure the task fails correctly
    ^^^^^^^
  File "/opt/airflow/dags/my_first_dbt_dag.py", line 45, in run_dbt_model
    result = subprocess.run(
             ^^^^^^^^^^^^^^^
  File "/usr/local/lib/python3.12/subprocess.py", line 571, in run
    raise CalledProcessError(retcode, process.args,
subprocess.CalledProcessError: Command '['dbt', 'run', '--project-dir', '/opt/dbt-project', '--profiles-dir', '/opt/dbt-project', '--select', 'my_first_dbt_model']' returned non-zero exit status 1.
[2025-01-15T20:48:05.988+0000] {taskinstance.py:1225} INFO - Marking task as UP_FOR_RETRY. dag_id=my_first_dbt_dag, task_id=run_dbt_model, run_id=scheduled__2025-01-14T00:00:00+00:00, execution_date=20250114T000000, start_date=20250115T204738, end_date=20250115T204805
[2025-01-15T20:48:06.119+0000] {taskinstance.py:340} INFO - ::group::Post task execution logs
[2025-01-15T20:48:06.122+0000] {standard_task_runner.py:124} ERROR - Failed to execute job 24 for task run_dbt_model (Command '['dbt', 'run', '--project-dir', '/opt/dbt-project', '--profiles-dir', '/opt/dbt-project', '--select', 'my_first_dbt_model']' returned non-zero exit status 1.; 7457)
Traceback (most recent call last):
  File "/home/airflow/.local/lib/python3.12/site-packages/airflow/task/task_runner/standard_task_runner.py", line 117, in _start_by_fork
    ret = args.func(args, dag=self.dag)
          ^^^^^^^^^^^^^^^^^^^^^^^^^^^^^
  File "/home/airflow/.local/lib/python3.12/site-packages/airflow/cli/cli_config.py", line 49, in command
    return func(*args, **kwargs)
           ^^^^^^^^^^^^^^^^^^^^^
  File "/home/airflow/.local/lib/python3.12/site-packages/airflow/utils/cli.py", line 116, in wrapper
    return f(*args, **kwargs)
           ^^^^^^^^^^^^^^^^^^
  File "/home/airflow/.local/lib/python3.12/site-packages/airflow/cli/commands/task_command.py", line 483, in task_run
    task_return_code = _run_task_by_selected_method(args, _dag, ti)
                       ^^^^^^^^^^^^^^^^^^^^^^^^^^^^^^^^^^^^^^^^^^^^
  File "/home/airflow/.local/lib/python3.12/site-packages/airflow/cli/commands/task_command.py", line 256, in _run_task_by_selected_method
    return _run_raw_task(args, ti)
           ^^^^^^^^^^^^^^^^^^^^^^^
  File "/home/airflow/.local/lib/python3.12/site-packages/airflow/cli/commands/task_command.py", line 341, in _run_raw_task
    return ti._run_raw_task(
           ^^^^^^^^^^^^^^^^^
  File "/home/airflow/.local/lib/python3.12/site-packages/airflow/utils/session.py", line 97, in wrapper
    return func(*args, session=session, **kwargs)
           ^^^^^^^^^^^^^^^^^^^^^^^^^^^^^^^^^^^^^^
  File "/home/airflow/.local/lib/python3.12/site-packages/airflow/models/taskinstance.py", line 3005, in _run_raw_task
    return _run_raw_task(
           ^^^^^^^^^^^^^^
  File "/home/airflow/.local/lib/python3.12/site-packages/airflow/models/taskinstance.py", line 273, in _run_raw_task
    TaskInstance._execute_task_with_callbacks(
  File "/home/airflow/.local/lib/python3.12/site-packages/airflow/models/taskinstance.py", line 3159, in _execute_task_with_callbacks
    result = self._execute_task(context, task_orig)
             ^^^^^^^^^^^^^^^^^^^^^^^^^^^^^^^^^^^^^^
  File "/home/airflow/.local/lib/python3.12/site-packages/airflow/models/taskinstance.py", line 3183, in _execute_task
    return _execute_task(self, context, task_orig)
           ^^^^^^^^^^^^^^^^^^^^^^^^^^^^^^^^^^^^^^^
  File "/home/airflow/.local/lib/python3.12/site-packages/airflow/models/taskinstance.py", line 767, in _execute_task
    result = _execute_callable(context=context, **execute_callable_kwargs)
             ^^^^^^^^^^^^^^^^^^^^^^^^^^^^^^^^^^^^^^^^^^^^^^^^^^^^^^^^^^^^^
  File "/home/airflow/.local/lib/python3.12/site-packages/airflow/models/taskinstance.py", line 733, in _execute_callable
    return ExecutionCallableRunner(
           ^^^^^^^^^^^^^^^^^^^^^^^^
  File "/home/airflow/.local/lib/python3.12/site-packages/airflow/utils/operator_helpers.py", line 252, in run
    return self.func(*args, **kwargs)
           ^^^^^^^^^^^^^^^^^^^^^^^^^^
  File "/home/airflow/.local/lib/python3.12/site-packages/airflow/models/baseoperator.py", line 422, in wrapper
    return func(self, *args, **kwargs)
           ^^^^^^^^^^^^^^^^^^^^^^^^^^^
  File "/home/airflow/.local/lib/python3.12/site-packages/airflow/operators/python.py", line 238, in execute
    return_value = self.execute_callable()
                   ^^^^^^^^^^^^^^^^^^^^^^^
  File "/home/airflow/.local/lib/python3.12/site-packages/airflow/operators/python.py", line 256, in execute_callable
    return runner.run(*self.op_args, **self.op_kwargs)
           ^^^^^^^^^^^^^^^^^^^^^^^^^^^^^^^^^^^^^^^^^^^
  File "/home/airflow/.local/lib/python3.12/site-packages/airflow/utils/operator_helpers.py", line 252, in run
    return self.func(*args, **kwargs)
           ^^^^^^^^^^^^^^^^^^^^^^^^^^
  File "/opt/airflow/dags/my_first_dbt_dag.py", line 54, in run_dbt_model
    raise e  # Raise again to make sure the task fails correctly
    ^^^^^^^
  File "/opt/airflow/dags/my_first_dbt_dag.py", line 45, in run_dbt_model
    result = subprocess.run(
             ^^^^^^^^^^^^^^^
  File "/usr/local/lib/python3.12/subprocess.py", line 571, in run
    raise CalledProcessError(retcode, process.args,
subprocess.CalledProcessError: Command '['dbt', 'run', '--project-dir', '/opt/dbt-project', '--profiles-dir', '/opt/dbt-project', '--select', 'my_first_dbt_model']' returned non-zero exit status 1.
[2025-01-15T20:48:06.194+0000] {local_task_job_runner.py:266} INFO - Task exited with return code 1
[2025-01-15T20:48:06.322+0000] {taskinstance.py:3895} INFO - 0 downstream tasks scheduled from follow-on schedule check
[2025-01-15T20:48:06.327+0000] {local_task_job_runner.py:245} INFO - ::endgroup::
[2025-01-15T20:48:06.340+0000] {standard_task_runner.py:217} INFO - Process not found (most likely exited), stop collecting metrics
